<mujoco model="g1_29dof scene">
  <compiler angle="radian" meshdir="meshes/"/>

  <option timestep="0.005"/>

  <visual>
    <global azimuth="-130" elevation="-20"/>
    <headlight ambient="0.3 0.3 0.3" diffuse="0.6 0.6 0.6" specular="0 0 0"/>
    <rgba haze="0.15 0.25 0.35 1"/>
  </visual>

  <statistic extent="2" center="0 0 0.5"/>

  <default>
    <default class="torso_motor">
      <joint armature="0.01" damping="0.05" frictionloss="0.2"/>
    </default>
    <default class="leg_motor">
      <joint armature="0.01" damping="0.05" frictionloss="0.2"/>
    </default>
    <default class="ankle_motor">
      <joint armature="0.01" damping="0.05" frictionloss="0.2"/>
    </default>
    <default class="arm_motor">
      <joint armature="0.01" damping="0.05" frictionloss="0.2"/>
    </default>
    <default class="wrist_motor">
      <joint armature="0.01" damping="0.05" frictionloss="0.1"/>
    </default>
  </default>

  <asset>
    <texture type="skybox" builtin="gradient" rgb1="0.3 0.5 0.7" rgb2="0 0 0" width="512" height="3072"/>
    <texture type="2d" name="groundplane" builtin="checker" mark="edge" rgb1="0.2 0.3 0.4" rgb2="0.1 0.2 0.3" markrgb="0.8 0.8 0.8" width="300" height="300"/>
    <material name="groundplane" texture="groundplane" texuniform="true" texrepeat="5 5" reflectance="0.2"/>
    <mesh name="pelvis" file="pelvis.STL"/>
    <mesh name="pelvis_contour_link" file="pelvis_contour_link.STL"/>
    <mesh name="left_hip_pitch_link" file="left_hip_pitch_link.STL"/>
    <mesh name="left_hip_roll_link" file="left_hip_roll_link.STL"/>
    <mesh name="left_hip_yaw_link" file="left_hip_yaw_link.STL"/>
    <mesh name="left_knee_link" file="left_knee_link.STL"/>
    <mesh name="left_ankle_pitch_link" file="left_ankle_pitch_link.STL"/>
    <mesh name="left_ankle_roll_link" file="left_ankle_roll_link.STL"/>
    <mesh name="right_hip_pitch_link" file="right_hip_pitch_link.STL"/>
    <mesh name="right_hip_roll_link" file="right_hip_roll_link.STL"/>
    <mesh name="right_hip_yaw_link" file="right_hip_yaw_link.STL"/>
    <mesh name="right_knee_link" file="right_knee_link.STL"/>
    <mesh name="right_ankle_pitch_link" file="right_ankle_pitch_link.STL"/>
    <mesh name="right_ankle_roll_link" file="right_ankle_roll_link.STL"/>
    <mesh name="waist_yaw_link" file="waist_yaw_link.STL"/>
    <mesh name="waist_roll_link" file="waist_roll_link.STL"/>
    <mesh name="torso_link" file="torso_link.STL"/>
    <mesh name="logo_link" file="logo_link.STL"/>
    <mesh name="head_link" file="head_link.STL"/>
    <mesh name="waist_support_link" file="waist_support_link.STL"/>
    <mesh name="left_shoulder_pitch_link" file="left_shoulder_pitch_link.STL"/>
    <mesh name="left_shoulder_roll_link" file="left_shoulder_roll_link.STL"/>
    <mesh name="left_shoulder_yaw_link" file="left_shoulder_yaw_link.STL"/>
    <mesh name="left_elbow_link" file="left_elbow_link.STL"/>
    <mesh name="left_wrist_roll_link" file="left_wrist_roll_link.STL"/>
    <mesh name="left_wrist_pitch_link" file="left_wrist_pitch_link.STL"/>
    <mesh name="left_wrist_yaw_link" file="left_wrist_yaw_link.STL"/>
    <mesh name="left_rubber_hand" file="left_rubber_hand.STL"/>
    <mesh name="right_shoulder_pitch_link" file="right_shoulder_pitch_link.STL"/>
    <mesh name="right_shoulder_roll_link" file="right_shoulder_roll_link.STL"/>
    <mesh name="right_shoulder_yaw_link" file="right_shoulder_yaw_link.STL"/>
    <mesh name="right_elbow_link" file="right_elbow_link.STL"/>
    <mesh name="right_wrist_roll_link" file="right_wrist_roll_link.STL"/>
    <mesh name="right_wrist_pitch_link" file="right_wrist_pitch_link.STL"/>
    <mesh name="right_wrist_yaw_link" file="right_wrist_yaw_link.STL"/>
    <mesh name="right_rubber_hand" file="right_rubber_hand.STL"/>
    <hfield name="perlin_hfield" size="1 0.75 0.2 0.2" file="../height_field.png"/>
    <hfield name="image_hfield" size="1 1 0.02 0.1" file="../unitree_hfield.png"/>
  </asset>

  <worldbody>
    <geom name="floor" size="0 0 0.05" type="plane" material="groundplane"/>
    <geom size="0.5 0.75 0.1" pos="1.5 0 0.1" type="box"/>
    <geom size="0.5 0.25" pos="1.5 0 0.25" type="cylinder"/>
    <geom size="1.5 0.75 0.05" pos="2 2 0.5" quat="0.968912 0 -0.247404 0" type="box"/>
    <geom size="0.1 0.75 0.075" pos="1.2 4 0.075" type="box"/>
    <geom size="0.1 0.75 0.075" pos="1.4 4 0.225" type="box"/>
    <geom size="0.1 0.75 0.075" pos="1.6 4 0.375" type="box"/>
    <geom size="0.1 0.75 0.075" pos="1.8 4 0.525" type="box"/>
    <geom size="0.1 0.75 0.075" pos="2 4 0.675" type="box"/>
    <geom size="0.1 0.75 0.075" pos="2.2 4 0.825" type="box"/>
    <geom size="0.1 0.75 0.075" pos="2.4 4 0.975" type="box"/>
    <geom size="0.1 0.75 0.075" pos="2.6 4 1.125" type="box"/>
    <geom size="0.1 0.75 0.075" pos="2.8 4 1.275" type="box"/>
    <geom size="0.1 0.75 0.075" pos="3 4 1.425" type="box"/>
    <geom size="0.1 0.75 0.025" pos="1.2 6 0.075" type="box"/>
    <geom size="0.1 0.75 0.025" pos="1.4 6 0.225" type="box"/>
    <geom size="0.1 0.75 0.025" pos="1.6 6 0.375" type="box"/>
    <geom size="0.1 0.75 0.025" pos="1.8 6 0.525" type="box"/>
    <geom size="0.1 0.75 0.025" pos="2 6 0.675" type="box"/>
    <geom size="0.1 0.75 0.025" pos="2.2 6 0.825" type="box"/>
    <geom size="0.1 0.75 0.025" pos="2.4 6 0.975" type="box"/>
    <geom size="0.1 0.75 0.025" pos="2.6 6 1.125" type="box"/>
    <geom size="0.1 0.75 0.025" pos="2.8 6 1.275" type="box"/>
    <geom size="0.1 0.75 0.025" pos="3 6 1.425" type="box"/>
    <geom size="0.266742 0.232492 0.27156" pos="-2.30046 5.23013 -0.25" quat="0.993751 -0.0901152 0.0458405 -0.0472867" type="box"/>
    <geom size="0.250527 0.241202 0.22646" pos="-2.30046 5.39152 -0.25" quat="0.994786 0.0430479 0.00449633 0.0923488" type="box"/>
    <geom size="0.274457 0.249924 0.228016" pos="-2.30046 5.63271 -0.25" quat="0.992727 0.0716013 -0.00536137 0.0966337" type="box"/>
    <geom size="0.243255 0.225357 0.266291" pos="-2.30046 5.79899 -0.25" quat="0.994238 0.095253 0.00794678 -0.0485199" type="box"/>
    <geom size="0.239851 0.242851 0.264747" pos="-2.30046 5.97354 -0.25" quat="0.996408 -0.0410653 -0.0363795 0.0645007" type="box"/>
    <geom size="0.257208 0.237119 0.228783" pos="-2.30046 6.17705 -0.25" quat="0.993766 -0.0883473 0.0169574 -0.0658528" type="box"/>
    <geom size="0.247546 0.259472 0.239283" pos="-2.30046 6.40718 -0.25" quat="0.995896 0.0430566 -0.0453996 0.0653849" type="box"/>
    <geom size="0.254759 0.231431 0.268237" pos="-2.30046 6.62934 -0.25" quat="0.997299 0.0446018 -0.0569389 -0.0127522" type="box"/>
    <geom size="0.248606 0.229864 0.255727" pos="-2.1404 5.16945 -0.25" quat="0.991471 0.031407 0.0996401 0.0779151" type="box"/>
    <geom size="0.229151 0.258672 0.27348" pos="-2.1404 5.36544 -0.25" quat="0.997149 -0.0128017 0.0629925 0.0395216" type="box"/>
    <geom size="0.234027 0.265794 0.25539" pos="-2.1404 5.56486 -0.25" quat="0.99663 0.0781837 0.0241239 0.00579802" type="box"/>
    <geom size="0.263059 0.229768 0.236862" pos="-2.1404 5.71829 -0.25" quat="0.996518 0.0410395 0.0635172 0.0351196" type="box"/>
    <geom size="0.2583 0.237773 0.241464" pos="-2.1404 5.93702 -0.25" quat="0.993495 0.066005 -0.0639095 0.0672859" type="box"/>
    <geom size="0.236535 0.243698 0.240333" pos="-2.1404 6.13992 -0.25" quat="0.996553 0.0391242 0.073141 0.00114009" type="box"/>
    <geom size="0.253139 0.2448 0.250481" pos="-2.1404 6.30177 -0.25" quat="0.992974 -0.0933852 -0.0520911 0.0506838" type="box"/>
    <geom size="0.22763 0.266496 0.257729" pos="-2.1404 6.50787 -0.25" quat="0.997888 0.0606443 -0.0134636 0.0189932" type="box"/>
    <geom size="0.262622 0.244116 0.260708" pos="-1.89136 5.24127 -0.25" quat="0.987536 0.101695 0.085503 -0.0843854" type="box"/>
    <geom size="0.260277 0.273954 0.273378" pos="-1.89136 5.47195 -0.25" quat="0.995871 0.0257632 -0.0294562 0.081908" type="box"/>
    <geom size="0.234109 0.236708 0.245686" pos="-1.89136 5.71021 -0.25" quat="0.989719 -0.0873416 -0.0804403 -0.0797326" type="box"/>
    <geom size="0.239829 0.238001 0.239822" pos="-1.89136 5.95535 -0.25" quat="0.995242 0.0543037 -0.0786655 0.0188837" type="box"/>
    <geom size="0.246215 0.232195 0.271144" pos="-1.89136 6.18598 -0.25" quat="0.998225 -0.0115677 -0.0564298 0.0150963" type="box"/>
    <geom size="0.235239 0.234808 0.269216" pos="-1.89136 6.42514 -0.25" quat="0.996845 -0.00396416 -0.0791593 0.00429023" type="box"/>
    <geom size="0.260384 0.229384 0.266308" pos="-1.89136 6.63208 -0.25" quat="0.994254 -0.0384712 -0.0150134 -0.0987554" type="box"/>
    <geom size="0.226822 0.256204 0.259011" pos="-1.89136 6.86778 -0.25" quat="0.991797 -0.0462234 0.0805548 0.087828" type="box"/>
    <geom size="0.263252 0.240266 0.248418" pos="-1.67983 5.21624 -0.25" quat="0.99978 -0.00327672 -0.0206882 -0.00115369" type="box"/>
    <geom size="0.266727 0.248447 0.233137" pos="-1.67983 5.38686 -0.25" quat="0.995283 0.0740722 -0.01386 -0.0610988" type="box"/>
    <geom size="0.232468 0.252304 0.26126" pos="-1.67983 5.59107 -0.25" quat="0.993521 0.0504217 -0.0800277 -0.0630058" type="box"/>
    <geom size="0.253563 0.247954 0.246345" pos="-1.67983 5.74184 -0.25" quat="0.994073 0.076453 0.0588879 0.0500654" type="box"/>
    <geom size="0.270723 0.226925 0.250327" pos="-1.67983 5.90536 -0.25" quat="0.997718 0.0212456 -0.0321111 -0.0554633" type="box"/>
    <geom size="0.270751 0.260006 0.262107" pos="-1.67983 6.15297 -0.25" quat="0.995412 0.0515909 -0.0704505 -0.039113" type="box"/>
    <geom size="0.234509 0.240716 0.266603" pos="-1.67983 6.36674 -0.25" quat="0.992225 0.0757518 -0.0927947 -0.0337777" type="box"/>
    <geom size="0.260492 0.270224 0.239717" pos="-1.67983 6.55164 -0.25" quat="0.989293 -0.101003 -0.0600367 -0.0865661" type="box"/>
    <geom size="0.261368 0.252317 0.265469" pos="-1.47652 5.24394 -0.25" quat="0.998505 -0.029501 0.0455644 -0.00644001" type="box"/>
    <geom size="0.244091 0.256547 0.258388" pos="-1.47652 5.48041 -0.25" quat="0.993333 -0.0691381 -0.0913624 -0.012754" type="box"/>
    <geom size="0.267137 0.230056 0.244526" pos="-1.47652 5.67124 -0.25" quat="0.994026 0.0512544 0.0672139 0.0690509" type="box"/>
    <geom size="0.259414 0.24467 0.244432" pos="-1.47652 5.8451 -0.25" quat="0.998479 0.0447734 0.032009 0.00308249" type="box"/>
    <geom size="0.264359 0.232363 0.24142" pos="-1.47652 6.01058 -0.25" quat="0.99884 0.0244633 -0.0317262 0.0267197" type="box"/>
    <geom size="0.247317 0.258437 0.271088" pos="-1.47652 6.23782 -0.25" quat="0.988586 0.0829072 0.0979015 0.0789845" type="box"/>
    <geom size="0.241933 0.231386 0.261685" pos="-1.47652 6.44931 -0.25" quat="0.995823 0.079174 -0.0258125 0.0374298" type="box"/>
    <geom size="0.247217 0.229765 0.245798" pos="-1.47652 6.68457 -0.25" quat="0.997271 0.0534467 -0.047688 -0.0178888" type="box"/>
    <geom size="0.270943 0.266009 0.229608" pos="-1.28368 5.23345 -0.25" quat="0.999 0.0441556 -0.00568443 -0.00404746" type="box"/>
    <geom size="0.270572 0.261042 0.247756" pos="-1.28368 5.44668 -0.25" quat="0.997327 -0.0358532 -0.00277686 -0.0636013" type="box"/>
    <geom size="0.258195 0.246937 0.240368" pos="-1.28368 5.6111 -0.25" quat="0.993631 0.0901787 0.0664262 -0.0123374" type="box"/>
    <geom size="0.274671 0.274001 0.273578" pos="-1.28368 5.84952 -0.25" quat="0.991635 -0.0266047 -0.0963811 -0.081629" type="box"/>
    <geom size="0.257282 0.259301 0.249792" pos="-1.28368 6.08784 -0.25" quat="0.995082 -0.090676 0.0395653 0.00491179" type="box"/>
    <geom size="0.268407 0.246082 0.230341" pos="-1.28368 6.2683 -0.25" quat="0.998726 -0.00599956 0.0497762 0.00563828" type="box"/>
    <geom size="0.269662 0.260817 0.233988" pos="-1.28368 6.45297 -0.25" quat="0.998961 0.0178416 -0.0195548 -0.0370908" type="box"/>
    <geom size="0.227852 0.270414 0.226953" pos="-1.28368 6.65495 -0.25" quat="0.997681 0.0365475 0.0573882 -0.00196992" type="box"/>
    <geom size="0.245682 0.263546 0.236967" pos="-1.10222 5.16989 -0.25" quat="0.997629 -0.0472719 -0.0256628 -0.0429432" type="box"/>
    <geom size="0.251669 0.235787 0.249144" pos="-1.10222 5.37243 -0.25" quat="0.994162 0.0901313 -0.0463003 -0.0370621" type="box"/>
    <geom size="0.22749 0.242854 0.24637" pos="-1.10222 5.61375 -0.25" quat="0.996731 0.00575148 -0.054869 0.0590174" type="box"/>
    <geom size="0.227619 0.243573 0.242043" pos="-1.10222 5.7708 -0.25" quat="0.992071 0.0645583 0.0818399 0.0702155" type="box"/>
    <geom size="0.235438 0.226901 0.248928" pos="-1.10222 6.01023 -0.25" quat="0.998712 -0.0366691 -0.0341377 0.00802318" type="box"/>
    <geom size="0.248997 0.264763 0.231145" pos="-1.10222 6.18265 -0.25" quat="0.995346 0.0173913 -0.0657011 0.0683182" type="box"/>
    <geom size="0.2512 0.266893 0.247394" pos="-1.10222 6.38878 -0.25" quat="0.995295 0.0890051 0.0371143 -0.00940244" type="box"/>
    <geom size="0.26421 0.244025 0.228375" pos="-1.10222 6.58774 -0.25" quat="0.994588 0.0617145 0.0193039 -0.0813177" type="box"/>
    <geom size="0.241298 0.244556 0.244557" pos="-0.918751 5.228 -0.25" quat="0.995398 0.0862003 0.0170372 -0.0382382" type="box"/>
    <geom size="0.241448 0.249885 0.260576" pos="-0.918751 5.47712 -0.25" quat="0.993097 -0.0230391 -0.0754324 -0.0868225" type="box"/>
    <geom size="0.230115 0.266885 0.234592" pos="-0.918751 5.65036 -0.25" quat="0.99531 0.0812194 -0.0289885 -0.0438359" type="box"/>
    <geom size="0.26967 0.228083 0.246322" pos="-0.918751 5.81674 -0.25" quat="0.994163 0.0365928 -0.0941832 -0.0378203" type="box"/>
    <geom size="0.265295 0.256809 0.226162" pos="-0.918751 5.97345 -0.25" quat="0.993415 -0.0668204 0.0152613 0.091806" type="box"/>
    <geom size="0.246375 0.235197 0.261826" pos="-0.918751 6.20823 -0.25" quat="0.998085 -0.0167086 -3.23881e-05 0.059555" type="box"/>
    <geom size="0.267185 0.230316 0.242699" pos="-0.918751 6.43958 -0.25" quat="0.992291 0.0862701 0.0653962 -0.0603213" type="box"/>
    <geom size="0.270107 0.240268 0.255792" pos="-0.918751 6.63359 -0.25" quat="0.999949 0.000285976 -0.00874304 0.00502747" type="box"/>
    <geom size="0.25344 0.255082 0.2651" pos="-0.68935 5.24897 -0.25" quat="0.995138 -0.00937491 0.0865993 -0.0459699" type="box"/>
    <geom size="0.272294 0.26237 0.26091" pos="-0.68935 5.46124 -0.25" quat="0.993864 -0.0164681 -0.0989128 -0.0466785" type="box"/>
    <geom size="0.237524 0.246979 0.228493" pos="-0.68935 5.68718 -0.25" quat="0.993466 -0.046793 0.0475913 -0.0925762" type="box"/>
    <geom size="0.245324 0.234611 0.230004" pos="-0.68935 5.87288 -0.25" quat="0.992709 -0.0208258 -0.0738731 -0.0929415" type="box"/>
    <geom size="0.24 0.233389 0.237907" pos="-0.68935 6.04109 -0.25" quat="0.993823 0.0580419 0.0180643 0.092851" type="box"/>
    <geom size="0.235266 0.240283 0.250677" pos="-0.68935 6.25517 -0.25" quat="0.996879 -0.0562852 0.0552583 0.00313433" type="box"/>
    <geom size="0.237196 0.234494 0.225783" pos="-0.68935 6.48256 -0.25" quat="0.998342 0.0190604 0.0390427 -0.0377651" type="box"/>
    <geom size="0.26914 0.245603 0.22875" pos="-0.68935 6.7204 -0.25" quat="0.997728 -0.00018196 0.0588826 -0.0327427" type="box"/>
    <geom size="0.266419 0.231934 0.225641" pos="-0.502482 5.24322 -0.25" quat="0.992348 -0.0775267 0.0960938 -0.000947034" type="box"/>
    <geom size="0.229888 0.233839 0.241121" pos="-0.502482 5.40844 -0.25" quat="0.995098 0.0210457 0.0655297 0.0710148" type="box"/>
    <geom size="0.239374 0.261347 0.245751" pos="-0.502482 5.5933 -0.25" quat="0.998469 -0.00762182 0.0107291 -0.0537229" type="box"/>
    <geom size="0.262198 0.248273 0.259949" pos="-0.502482 5.83357 -0.25" quat="0.99658 0.0461065 -0.0681468 0.00765244" type="box"/>
    <geom size="0.236854 0.229013 0.226582" pos="-0.502482 5.98721 -0.25" quat="0.992587 0.0420953 0.0900206 -0.0699624" type="box"/>
    <geom size="0.269748 0.2616 0.251415" pos="-0.502482 6.19181 -0.25" quat="0.998743 0.0321155 0.0371399 -0.0100996" type="box"/>
    <geom size="0.263278 0.271486 0.257957" pos="-0.502482 6.41129 -0.25" quat="0.993875 -0.0500247 -0.0976753 0.0130532" type="box"/>
    <geom size="0.26691 0.253504 0.26964" pos="-0.502482 6.57016 -0.25" quat="0.995647 -0.0509584 -0.0383918 0.067945" type="box"/>
    <geom pos="-1.5 4 0" type="hfield" hfield="perlin_hfield"/>
    <geom pos="-1.5 2 0" quat="0.707388 0 0 -0.706825" type="hfield" hfield="image_hfield"/>
    <light pos="0 0 1.5" dir="0 0 -1" directional="true"/>
    <body name="pelvis" pos="0 0 0.793">
      <inertial pos="0 0 -0.07605" quat="1 0 -0.000399148 0" mass="3.813" diaginertia="0.010549 0.0093089 0.0079184"/>
      <joint name="floating_base_joint" type="free" limited="false" actuatorfrclimited="false"/>
      <geom type="mesh" contype="0" conaffinity="0" group="1" density="0" rgba="0.2 0.2 0.2 1" mesh="pelvis"/>
      <geom type="mesh" contype="0" conaffinity="0" group="1" density="0" rgba="0.7 0.7 0.7 1" mesh="pelvis_contour_link"/>
      <geom type="mesh" rgba="0.7 0.7 0.7 1" mesh="pelvis_contour_link"/>
      <site name="imu" pos="0 0 0" size="0.01"/>
      <body name="left_hip_pitch_link" pos="0 0.064452 -0.1027">
        <inertial pos="0.002741 0.047791 -0.02606" quat="0.954862 0.293964 0.0302556 0.030122" mass="1.35" diaginertia="0.00181517 0.00153422 0.00116212"/>
        <joint name="left_hip_pitch_joint" class="leg_motor" pos="0 0 0" axis="0 1 0" range="-2.5307 2.8798" actuatorfrcrange="-88 88"/>
        <geom type="mesh" contype="0" conaffinity="0" group="1" density="0" rgba="0.2 0.2 0.2 1" mesh="left_hip_pitch_link"/>
        <geom type="mesh" rgba="0.2 0.2 0.2 1" mesh="left_hip_pitch_link"/>
        <body name="left_hip_roll_link" pos="0 0.052 -0.030465" quat="0.996179 0 -0.0873386 0">
          <inertial pos="0.029812 -0.001045 -0.087934" quat="0.977808 -1.97119e-05 0.205576 -0.0403793" mass="1.52" diaginertia="0.00254986 0.00241169 0.00148755"/>
          <joint name="left_hip_roll_joint" class="leg_motor" pos="0 0 0" axis="1 0 0" range="-0.5236 2.9671" actuatorfrcrange="-88 88"/>
          <geom type="mesh" contype="0" conaffinity="0" group="1" density="0" rgba="0.7 0.7 0.7 1" mesh="left_hip_roll_link"/>
          <geom type="mesh" rgba="0.7 0.7 0.7 1" mesh="left_hip_roll_link"/>
          <body name="left_hip_yaw_link" pos="0.025001 0 -0.12412">
            <inertial pos="-0.057709 -0.010981 -0.15078" quat="0.600598 0.15832 0.223482 0.751181" mass="1.702" diaginertia="0.00776166 0.00717575 0.00160139"/>
            <joint name="left_hip_yaw_joint" class="leg_motor" pos="0 0 0" axis="0 0 1" range="-2.7576 2.7576" actuatorfrcrange="-88 88"/>
            <geom type="mesh" contype="0" conaffinity="0" group="1" density="0" rgba="0.7 0.7 0.7 1" mesh="left_hip_yaw_link"/>
            <geom type="mesh" rgba="0.7 0.7 0.7 1" mesh="left_hip_yaw_link"/>
            <body name="left_knee_link" pos="-0.078273 0.0021489 -0.17734" quat="0.996179 0 0.0873386 0">
              <inertial pos="0.005457 0.003964 -0.12074" quat="0.923418 -0.0327699 0.0158246 0.382067" mass="1.932" diaginertia="0.0113804 0.0112778 0.00146458"/>
              <joint name="left_knee_joint" class="leg_motor" pos="0 0 0" axis="0 1 0" range="-0.087267 2.8798" actuatorfrcrange="-139 139"/>
              <geom type="mesh" contype="0" conaffinity="0" group="1" density="0" rgba="0.7 0.7 0.7 1" mesh="left_knee_link"/>
              <geom type="mesh" rgba="0.7 0.7 0.7 1" mesh="left_knee_link"/>
              <body name="left_ankle_pitch_link" pos="0 -9.4445e-05 -0.30001">
                <inertial pos="-0.007269 0 0.011137" quat="0.603053 0.369225 0.369225 0.603053" mass="0.074" diaginertia="1.89e-05 1.40805e-05 6.9195e-06"/>
                <joint name="left_ankle_pitch_joint" class="ankle_motor" pos="0 0 0" axis="0 1 0" range="-0.87267 0.5236" actuatorfrcrange="-50 50"/>
                <geom type="mesh" contype="0" conaffinity="0" group="1" density="0" rgba="0.7 0.7 0.7 1" mesh="left_ankle_pitch_link"/>
                <geom type="mesh" rgba="0.7 0.7 0.7 1" mesh="left_ankle_pitch_link"/>
                <body name="left_ankle_roll_link" pos="0 0 -0.017558">
                  <inertial pos="0.026505 0 -0.016425" quat="-0.000481092 0.728482 -0.000618967 0.685065" mass="0.608" diaginertia="0.00167218 0.0016161 0.000217621"/>
                  <joint name="left_ankle_roll_joint" class="ankle_motor" pos="0 0 0" axis="1 0 0" range="-0.2618 0.2618" actuatorfrcrange="-50 50"/>
                  <geom type="mesh" contype="0" conaffinity="0" group="1" density="0" rgba="0.2 0.2 0.2 1" mesh="left_ankle_roll_link"/>
                  <geom size="0.005" pos="-0.05 0.025 -0.03" rgba="0.2 0.2 0.2 1"/>
                  <geom size="0.005" pos="-0.05 -0.025 -0.03" rgba="0.2 0.2 0.2 1"/>
                  <geom size="0.005" pos="0.12 0.03 -0.03" rgba="0.2 0.2 0.2 1"/>
                  <geom size="0.005" pos="0.12 -0.03 -0.03" rgba="0.2 0.2 0.2 1"/>
                </body>
              </body>
            </body>
          </body>
        </body>
      </body>
      <body name="right_hip_pitch_link" pos="0 -0.064452 -0.1027">
        <inertial pos="0.002741 -0.047791 -0.02606" quat="0.954862 -0.293964 0.0302556 -0.030122" mass="1.35" diaginertia="0.00181517 0.00153422 0.00116212"/>
        <joint name="right_hip_pitch_joint" class="leg_motor" pos="0 0 0" axis="0 1 0" range="-2.5307 2.8798" actuatorfrcrange="-88 88"/>
        <geom type="mesh" contype="0" conaffinity="0" group="1" density="0" rgba="0.2 0.2 0.2 1" mesh="right_hip_pitch_link"/>
        <geom type="mesh" rgba="0.2 0.2 0.2 1" mesh="right_hip_pitch_link"/>
        <body name="right_hip_roll_link" pos="0 -0.052 -0.030465" quat="0.996179 0 -0.0873386 0">
          <inertial pos="0.029812 0.001045 -0.087934" quat="0.977808 1.97119e-05 0.205576 0.0403793" mass="1.52" diaginertia="0.00254986 0.00241169 0.00148755"/>
          <joint name="right_hip_roll_joint" class="leg_motor" pos="0 0 0" axis="1 0 0" range="-2.9671 0.5236" actuatorfrcrange="-88 88"/>
          <geom type="mesh" contype="0" conaffinity="0" group="1" density="0" rgba="0.7 0.7 0.7 1" mesh="right_hip_roll_link"/>
          <geom type="mesh" rgba="0.7 0.7 0.7 1" mesh="right_hip_roll_link"/>
          <body name="right_hip_yaw_link" pos="0.025001 0 -0.12412">
            <inertial pos="-0.057709 0.010981 -0.15078" quat="0.751181 0.223482 0.15832 0.600598" mass="1.702" diaginertia="0.00776166 0.00717575 0.00160139"/>
            <joint name="right_hip_yaw_joint" class="leg_motor" pos="0 0 0" axis="0 0 1" range="-2.7576 2.7576" actuatorfrcrange="-88 88"/>
            <geom type="mesh" contype="0" conaffinity="0" group="1" density="0" rgba="0.7 0.7 0.7 1" mesh="right_hip_yaw_link"/>
            <geom type="mesh" rgba="0.7 0.7 0.7 1" mesh="right_hip_yaw_link"/>
            <body name="right_knee_link" pos="-0.078273 -0.0021489 -0.17734" quat="0.996179 0 0.0873386 0">
              <inertial pos="0.005457 -0.003964 -0.12074" quat="0.923439 0.0345276 0.0116333 -0.382012" mass="1.932" diaginertia="0.011374 0.0112843 0.00146452"/>
              <joint name="right_knee_joint" class="leg_motor" pos="0 0 0" axis="0 1 0" range="-0.087267 2.8798" actuatorfrcrange="-139 139"/>
              <geom type="mesh" contype="0" conaffinity="0" group="1" density="0" rgba="0.7 0.7 0.7 1" mesh="right_knee_link"/>
              <geom type="mesh" rgba="0.7 0.7 0.7 1" mesh="right_knee_link"/>
              <body name="right_ankle_pitch_link" pos="0 9.4445e-05 -0.30001">
                <inertial pos="-0.007269 0 0.011137" quat="0.603053 0.369225 0.369225 0.603053" mass="0.074" diaginertia="1.89e-05 1.40805e-05 6.9195e-06"/>
                <joint name="right_ankle_pitch_joint" class="ankle_motor" pos="0 0 0" axis="0 1 0" range="-0.87267 0.5236" actuatorfrcrange="-50 50"/>
                <geom type="mesh" contype="0" conaffinity="0" group="1" density="0" rgba="0.7 0.7 0.7 1" mesh="right_ankle_pitch_link"/>
                <geom type="mesh" rgba="0.7 0.7 0.7 1" mesh="right_ankle_pitch_link"/>
                <body name="right_ankle_roll_link" pos="0 0 -0.017558">
                  <inertial pos="0.026505 0 -0.016425" quat="0.000481092 0.728482 0.000618967 0.685065" mass="0.608" diaginertia="0.00167218 0.0016161 0.000217621"/>
                  <joint name="right_ankle_roll_joint" class="ankle_motor" pos="0 0 0" axis="1 0 0" range="-0.2618 0.2618" actuatorfrcrange="-50 50"/>
                  <geom type="mesh" contype="0" conaffinity="0" group="1" density="0" rgba="0.2 0.2 0.2 1" mesh="right_ankle_roll_link"/>
                  <geom size="0.005" pos="-0.05 0.025 -0.03" rgba="0.2 0.2 0.2 1"/>
                  <geom size="0.005" pos="-0.05 -0.025 -0.03" rgba="0.2 0.2 0.2 1"/>
                  <geom size="0.005" pos="0.12 0.03 -0.03" rgba="0.2 0.2 0.2 1"/>
                  <geom size="0.005" pos="0.12 -0.03 -0.03" rgba="0.2 0.2 0.2 1"/>
                </body>
              </body>
            </body>
          </body>
        </body>
      </body>
      <body name="waist_yaw_link">
        <inertial pos="0.003964 0 0.018769" quat="-0.0178291 0.628464 0.0282471 0.777121" mass="0.244" diaginertia="0.000158561 0.000124229 9.67669e-05"/>
        <joint name="waist_yaw_joint" class="torso_motor" pos="0 0 0" axis="0 0 1" range="-2.618 2.618" actuatorfrcrange="-88 88"/>
        <geom type="mesh" contype="0" conaffinity="0" group="1" density="0" rgba="0.7 0.7 0.7 1" mesh="waist_yaw_link"/>
        <body name="waist_roll_link" pos="-0.0039635 0 0.035">
          <inertial pos="0 -0.000236 0.010111" quat="0.99979 0.020492 0 0" mass="0.047" diaginertia="7.515e-06 6.40206e-06 3.98394e-06"/>
          <joint name="waist_roll_joint" class="torso_motor" pos="0 0 0" axis="1 0 0" range="-0.52 0.52" actuatorfrcrange="-50 50"/>
          <geom type="mesh" contype="0" conaffinity="0" group="1" density="0" rgba="0.7 0.7 0.7 1" mesh="waist_roll_link"/>
          <site name="secondary_imu" pos="-0.03959 -0.00224 0.13792" size="0.01"/>
          <body name="torso_link" pos="0 0 0.019">
            <inertial pos="0.00331658 0.000261533 0.179856" quat="0.999831 0.000376204 0.0179895 -0.00377704" mass="9.598" diaginertia="0.12407 0.111951 0.0325382"/>
            <joint name="waist_pitch_joint" class="torso_motor" pos="0 0 0" axis="0 1 0" range="-0.52 0.52" actuatorfrcrange="-50 50"/>
            <geom type="mesh" contype="0" conaffinity="0" group="1" density="0" rgba="0.7 0.7 0.7 1" mesh="torso_link"/>
            <geom type="mesh" rgba="0.7 0.7 0.7 1" mesh="torso_link"/>
            <geom pos="0.0039635 0 -0.054" quat="1 0 0 0" type="mesh" contype="0" conaffinity="0" group="1" density="0" rgba="0.2 0.2 0.2 1" mesh="logo_link"/>
            <geom pos="0.0039635 0 -0.054" quat="1 0 0 0" type="mesh" rgba="0.2 0.2 0.2 1" mesh="logo_link"/>
            <geom pos="0.0039635 0 -0.054" type="mesh" contype="0" conaffinity="0" group="1" density="0" rgba="0.2 0.2 0.2 1" mesh="head_link"/>
            <geom pos="0.0039635 0 -0.054" type="mesh" rgba="0.2 0.2 0.2 1" mesh="head_link"/>
            <geom pos="0.0039635 0 -0.054" quat="1 0 0 0" type="mesh" contype="0" conaffinity="0" group="1" density="0" rgba="0.7 0.7 0.7 1" mesh="waist_support_link"/>
            <geom pos="0.0039635 0 -0.054" quat="1 0 0 0" type="mesh" rgba="0.7 0.7 0.7 1" mesh="waist_support_link"/>
            <body name="left_shoulder_pitch_link" pos="0.0039563 0.10022 0.23778" quat="0.990264 0.139201 1.38722e-05 -9.86868e-05">
              <inertial pos="0 0.035892 -0.011628" quat="0.654152 0.0130458 -0.326267 0.68225" mass="0.718" diaginertia="0.000465864 0.000432842 0.000406394"/>
              <joint name="left_shoulder_pitch_joint" class="arm_motor" pos="0 0 0" axis="0 1 0" range="-3.0892 2.6704" actuatorfrcrange="-25 25"/>
              <geom type="mesh" contype="0" conaffinity="0" group="1" density="0" rgba="0.7 0.7 0.7 1" mesh="left_shoulder_pitch_link"/>
              <geom size="0.03 0.025" pos="0 0.04 -0.01" quat="0.707107 0 0.707107 0" type="cylinder" rgba="0.7 0.7 0.7 1"/>
              <body name="left_shoulder_roll_link" pos="0 0.038 -0.013831" quat="0.990268 -0.139172 0 0">
                <inertial pos="-0.000227 0.00727 -0.063243" quat="0.701256 -0.0196223 -0.00710317 0.712604" mass="0.643" diaginertia="0.000691311 0.000618011 0.000388977"/>
                <joint name="left_shoulder_roll_joint" class="arm_motor" pos="0 0 0" axis="1 0 0" range="-1.5882 2.2515" actuatorfrcrange="-25 25"/>
                <geom type="mesh" contype="0" conaffinity="0" group="1" density="0" rgba="0.7 0.7 0.7 1" mesh="left_shoulder_roll_link"/>
                <geom size="0.03 0.015" pos="-0.004 0.006 -0.053" type="cylinder" rgba="0.7 0.7 0.7 1"/>
                <body name="left_shoulder_yaw_link" pos="0 0.00624 -0.1032">
                  <inertial pos="0.010773 -0.002949 -0.072009" quat="0.716879 -0.0964829 -0.0679942 0.687134" mass="0.734" diaginertia="0.00106187 0.00103217 0.000400661"/>
                  <joint name="left_shoulder_yaw_joint" class="arm_motor" pos="0 0 0" axis="0 0 1" range="-2.618 2.618" actuatorfrcrange="-25 25"/>
                  <geom type="mesh" contype="0" conaffinity="0" group="1" density="0" rgba="0.7 0.7 0.7 1" mesh="left_shoulder_yaw_link"/>
                  <geom type="mesh" rgba="0.7 0.7 0.7 1" mesh="left_shoulder_yaw_link"/>
                  <body name="left_elbow_link" pos="0.015783 0 -0.080518">
                    <inertial pos="0.064956 0.004454 -0.010062" quat="0.541765 0.636132 0.388821 0.388129" mass="0.6" diaginertia="0.000443035 0.000421612 0.000259353"/>
                    <joint name="left_elbow_joint" class="arm_motor" pos="0 0 0" axis="0 1 0" range="-1.0472 2.0944" actuatorfrcrange="-25 25"/>
                    <geom type="mesh" contype="0" conaffinity="0" group="1" density="0" rgba="0.7 0.7 0.7 1" mesh="left_elbow_link"/>
                    <geom type="mesh" rgba="0.7 0.7 0.7 1" mesh="left_elbow_link"/>
                    <body name="left_wrist_roll_link" pos="0.1 0.00188791 -0.01">
                      <inertial pos="0.0171394 0.000537591 4.8864e-07" quat="0.575338 0.411667 -0.574906 0.411094" mass="0.085445" diaginertia="5.48211e-05 4.96646e-05 3.57798e-05"/>
                      <joint name="left_wrist_roll_joint" class="arm_motor" pos="0 0 0" axis="1 0 0" range="-1.97222 1.97222" actuatorfrcrange="-25 25"/>
                      <geom type="mesh" contype="0" conaffinity="0" group="1" density="0" rgba="0.7 0.7 0.7 1" mesh="left_wrist_roll_link"/>
                      <geom type="mesh" rgba="0.7 0.7 0.7 1" mesh="left_wrist_roll_link"/>
                      <body name="left_wrist_pitch_link" pos="0.038 0 0">
                        <inertial pos="0.0229999 -0.00111685 -0.00111658" quat="0.249998 0.661363 0.293036 0.643608" mass="0.48405" diaginertia="0.000430353 0.000429873 0.000164648"/>
                        <joint name="left_wrist_pitch_joint" class="wrist_motor" pos="0 0 0" axis="0 1 0" range="-1.61443 1.61443" actuatorfrcrange="-5 5"/>
                        <geom type="mesh" contype="0" conaffinity="0" group="1" density="0" rgba="0.7 0.7 0.7 1" mesh="left_wrist_pitch_link"/>
                        <geom type="mesh" rgba="0.7 0.7 0.7 1" mesh="left_wrist_pitch_link"/>
                        <body name="left_wrist_yaw_link" pos="0.046 0 0">
                          <inertial pos="0.0708244 0.000191745 0.00161742" quat="0.510571 0.526295 0.468078 0.493188" mass="0.254576" diaginertia="0.000646113 0.000559993 0.000147566"/>
                          <joint name="left_wrist_yaw_joint" class="wrist_motor" pos="0 0 0" axis="0 0 1" range="-1.61443 1.61443" actuatorfrcrange="-5 5"/>
                          <geom type="mesh" contype="0" conaffinity="0" group="1" density="0" rgba="0.7 0.7 0.7 1" mesh="left_wrist_yaw_link"/>
                          <geom type="mesh" rgba="0.7 0.7 0.7 1" mesh="left_wrist_yaw_link"/>
                          <geom pos="0.0415 0.003 0" quat="1 0 0 0" type="mesh" contype="0" conaffinity="0" group="1" density="0" rgba="0.7 0.7 0.7 1" mesh="left_rubber_hand"/>
                        </body>
                      </body>
                    </body>
                  </body>
                </body>
              </body>
            </body>
            <body name="right_shoulder_pitch_link" pos="0.0039563 -0.10021 0.23778" quat="0.990264 -0.139201 1.38722e-05 9.86868e-05">
              <inertial pos="0 -0.035892 -0.011628" quat="0.68225 -0.326267 0.0130458 0.654152" mass="0.718" diaginertia="0.000465864 0.000432842 0.000406394"/>
              <joint name="right_shoulder_pitch_joint" class="arm_motor" pos="0 0 0" axis="0 1 0" range="-3.0892 2.6704" actuatorfrcrange="-25 25"/>
              <geom type="mesh" contype="0" conaffinity="0" group="1" density="0" rgba="0.7 0.7 0.7 1" mesh="right_shoulder_pitch_link"/>
              <geom size="0.03 0.025" pos="0 -0.04 -0.01" quat="0.707107 0 0.707107 0" type="cylinder" rgba="0.7 0.7 0.7 1"/>
              <body name="right_shoulder_roll_link" pos="0 -0.038 -0.013831" quat="0.990268 0.139172 0 0">
                <inertial pos="-0.000227 -0.00727 -0.063243" quat="0.712604 -0.00710317 -0.0196223 0.701256" mass="0.643" diaginertia="0.000691311 0.000618011 0.000388977"/>
                <joint name="right_shoulder_roll_joint" class="arm_motor" pos="0 0 0" axis="1 0 0" range="-2.2515 1.5882" actuatorfrcrange="-25 25"/>
                <geom type="mesh" contype="0" conaffinity="0" group="1" density="0" rgba="0.7 0.7 0.7 1" mesh="right_shoulder_roll_link"/>
                <geom size="0.03 0.015" pos="-0.004 -0.006 -0.053" type="cylinder" rgba="0.7 0.7 0.7 1"/>
                <body name="right_shoulder_yaw_link" pos="0 -0.00624 -0.1032">
                  <inertial pos="0.010773 0.002949 -0.072009" quat="0.687134 -0.0679942 -0.0964829 0.716879" mass="0.734" diaginertia="0.00106187 0.00103217 0.000400661"/>
                  <joint name="right_shoulder_yaw_joint" class="arm_motor" pos="0 0 0" axis="0 0 1" range="-2.618 2.618" actuatorfrcrange="-25 25"/>
                  <geom type="mesh" contype="0" conaffinity="0" group="1" density="0" rgba="0.7 0.7 0.7 1" mesh="right_shoulder_yaw_link"/>
                  <geom type="mesh" rgba="0.7 0.7 0.7 1" mesh="right_shoulder_yaw_link"/>
                  <body name="right_elbow_link" pos="0.015783 0 -0.080518">
                    <inertial pos="0.064956 -0.004454 -0.010062" quat="0.388129 0.388821 0.636132 0.541765" mass="0.6" diaginertia="0.000443035 0.000421612 0.000259353"/>
                    <joint name="right_elbow_joint" class="arm_motor" pos="0 0 0" axis="0 1 0" range="-1.0472 2.0944" actuatorfrcrange="-25 25"/>
                    <geom type="mesh" contype="0" conaffinity="0" group="1" density="0" rgba="0.7 0.7 0.7 1" mesh="right_elbow_link"/>
                    <geom type="mesh" rgba="0.7 0.7 0.7 1" mesh="right_elbow_link"/>
                    <body name="right_wrist_roll_link" pos="0.1 -0.00188791 -0.01">
                      <inertial pos="0.0171394 -0.000537591 4.8864e-07" quat="0.411667 0.575338 -0.411094 0.574906" mass="0.085445" diaginertia="5.48211e-05 4.96646e-05 3.57798e-05"/>
                      <joint name="right_wrist_roll_joint" class="arm_motor" pos="0 0 0" axis="1 0 0" range="-1.97222 1.97222" actuatorfrcrange="-25 25"/>
                      <geom type="mesh" contype="0" conaffinity="0" group="1" density="0" rgba="0.7 0.7 0.7 1" mesh="right_wrist_roll_link"/>
                      <geom type="mesh" rgba="0.7 0.7 0.7 1" mesh="right_wrist_roll_link"/>
                      <body name="right_wrist_pitch_link" pos="0.038 0 0">
                        <inertial pos="0.0229999 0.00111685 -0.00111658" quat="0.643608 0.293036 0.661363 0.249998" mass="0.48405" diaginertia="0.000430353 0.000429873 0.000164648"/>
                        <joint name="right_wrist_pitch_joint" class="wrist_motor" pos="0 0 0" axis="0 1 0" range="-1.61443 1.61443" actuatorfrcrange="-5 5"/>
                        <geom type="mesh" contype="0" conaffinity="0" group="1" density="0" rgba="0.7 0.7 0.7 1" mesh="right_wrist_pitch_link"/>
                        <geom type="mesh" rgba="0.7 0.7 0.7 1" mesh="right_wrist_pitch_link"/>
                        <body name="right_wrist_yaw_link" pos="0.046 0 0">
                          <inertial pos="0.0708244 -0.000191745 0.00161742" quat="0.493188 0.468078 0.526295 0.510571" mass="0.254576" diaginertia="0.000646113 0.000559993 0.000147566"/>
                          <joint name="right_wrist_yaw_joint" class="wrist_motor" pos="0 0 0" axis="0 0 1" range="-1.61443 1.61443" actuatorfrcrange="-5 5"/>
                          <geom type="mesh" contype="0" conaffinity="0" group="1" density="0" rgba="0.7 0.7 0.7 1" mesh="right_wrist_yaw_link"/>
                          <geom type="mesh" rgba="0.7 0.7 0.7 1" mesh="right_wrist_yaw_link"/>
                          <geom pos="0.0415 -0.003 0" quat="1 0 0 0" type="mesh" contype="0" conaffinity="0" group="1" density="0" rgba="0.7 0.7 0.7 1" mesh="right_rubber_hand"/>
                        </body>
                      </body>
                    </body>
                  </body>
                </body>
              </body>
            </body>
          </body>
        </body>
      </body>
    </body>
  </worldbody>

  <actuator>
    <general name="left_hip_pitch" joint="left_hip_pitch_joint" ctrlrange="-88 88"/>
    <general name="left_hip_roll" joint="left_hip_roll_joint" ctrlrange="-88 88"/>
    <general name="left_hip_yaw" joint="left_hip_yaw_joint" ctrlrange="-88 88"/>
    <general name="left_knee" joint="left_knee_joint" ctrlrange="-139 139"/>
    <general name="left_ankle_pitch" joint="left_ankle_pitch_joint" ctrlrange="-50 50"/>
    <general name="left_ankle_roll" joint="left_ankle_roll_joint" ctrlrange="-50 50"/>
    <general name="right_hip_pitch" joint="right_hip_pitch_joint" ctrlrange="-88 88"/>
    <general name="right_hip_roll" joint="right_hip_roll_joint" ctrlrange="-88 88"/>
    <general name="right_hip_yaw" joint="right_hip_yaw_joint" ctrlrange="-88 88"/>
    <general name="right_knee" joint="right_knee_joint" ctrlrange="-139 139"/>
    <general name="right_ankle_pitch" joint="right_ankle_pitch_joint" ctrlrange="-50 50"/>
    <general name="right_ankle_roll" joint="right_ankle_roll_joint" ctrlrange="-50 50"/>
    <general name="waist_yaw" joint="waist_yaw_joint" ctrlrange="-88 88"/>
    <general name="waist_roll" joint="waist_roll_joint" ctrlrange="-50 50"/>
    <general name="waist_pitch" joint="waist_pitch_joint" ctrlrange="-50 50"/>
    <general name="left_shoulder_pitch" joint="left_shoulder_pitch_joint" ctrlrange="-25 25"/>
    <general name="left_shoulder_roll" joint="left_shoulder_roll_joint" ctrlrange="-25 25"/>
    <general name="left_shoulder_yaw" joint="left_shoulder_yaw_joint" ctrlrange="-25 25"/>
    <general name="left_elbow" joint="left_elbow_joint" ctrlrange="-25 25"/>
    <general name="left_wrist_roll" joint="left_wrist_roll_joint" ctrlrange="-25 25"/>
    <general name="left_wrist_pitch" joint="left_wrist_pitch_joint" ctrlrange="-5 5"/>
    <general name="left_wrist_yaw" joint="left_wrist_yaw_joint" ctrlrange="-5 5"/>
    <general name="right_shoulder_pitch" joint="right_shoulder_pitch_joint" ctrlrange="-25 25"/>
    <general name="right_shoulder_roll" joint="right_shoulder_roll_joint" ctrlrange="-25 25"/>
    <general name="right_shoulder_yaw" joint="right_shoulder_yaw_joint" ctrlrange="-25 25"/>
    <general name="right_elbow" joint="right_elbow_joint" ctrlrange="-25 25"/>
    <general name="right_wrist_roll" joint="right_wrist_roll_joint" ctrlrange="-25 25"/>
    <general name="right_wrist_pitch" joint="right_wrist_pitch_joint" ctrlrange="-5 5"/>
    <general name="right_wrist_yaw" joint="right_wrist_yaw_joint" ctrlrange="-5 5"/>
  </actuator>

  <sensor>
    <jointpos joint="left_hip_pitch_joint" name="left_hip_pitch_pos"/>
    <jointpos joint="left_hip_roll_joint" name="left_hip_roll_pos"/>
    <jointpos joint="left_hip_yaw_joint" name="left_hip_yaw_pos"/>
    <jointpos joint="left_knee_joint" name="left_knee_pos"/>
    <jointpos joint="left_ankle_pitch_joint" name="left_ankle_pitch_pos"/>
    <jointpos joint="left_ankle_roll_joint" name="left_ankle_roll_pos"/>
    <jointpos joint="right_hip_pitch_joint" name="right_hip_pitch_pos"/>
    <jointpos joint="right_hip_roll_joint" name="right_hip_roll_pos"/>
    <jointpos joint="right_hip_yaw_joint" name="right_hip_yaw_pos"/>
    <jointpos joint="right_knee_joint" name="right_knee_pos"/>
    <jointpos joint="right_ankle_pitch_joint" name="right_ankle_pitch_pos"/>
    <jointpos joint="right_ankle_roll_joint" name="right_ankle_roll_pos"/>
    <jointpos joint="waist_yaw_joint" name="waist_yaw_pos"/>
    <jointpos joint="waist_roll_joint" name="waist_roll_pos"/>
    <jointpos joint="waist_pitch_joint" name="waist_pitch_pos"/>
    <jointpos joint="left_shoulder_pitch_joint" name="left_shoulder_pitch_pos"/>
    <jointpos joint="left_shoulder_roll_joint" name="left_shoulder_roll_pos"/>
    <jointpos joint="left_shoulder_yaw_joint" name="left_shoulder_yaw_pos"/>
    <jointpos joint="left_elbow_joint" name="left_elbow_pos"/>
    <jointpos joint="left_wrist_roll_joint" name="left_wrist_roll_pos"/>
    <jointpos joint="left_wrist_pitch_joint" name="left_wrist_pitch_pos"/>
    <jointpos joint="left_wrist_yaw_joint" name="left_wrist_yaw_pos"/>
    <jointpos joint="right_shoulder_pitch_joint" name="right_shoulder_pitch_pos"/>
    <jointpos joint="right_shoulder_roll_joint" name="right_shoulder_roll_pos"/>
    <jointpos joint="right_shoulder_yaw_joint" name="right_shoulder_yaw_pos"/>
    <jointpos joint="right_elbow_joint" name="right_elbow_pos"/>
    <jointpos joint="right_wrist_roll_joint" name="right_wrist_roll_pos"/>
    <jointpos joint="right_wrist_pitch_joint" name="right_wrist_pitch_pos"/>
    <jointpos joint="right_wrist_yaw_joint" name="right_wrist_yaw_pos"/>
    <jointvel joint="left_hip_pitch_joint" name="left_hip_pitch_vel"/>
    <jointvel joint="left_hip_roll_joint" name="left_hip_roll_vel"/>
    <jointvel joint="left_hip_yaw_joint" name="left_hip_yaw_vel"/>
    <jointvel joint="left_knee_joint" name="left_knee_vel"/>
    <jointvel joint="left_ankle_pitch_joint" name="left_ankle_pitch_vel"/>
    <jointvel joint="left_ankle_roll_joint" name="left_ankle_roll_vel"/>
    <jointvel joint="right_hip_pitch_joint" name="right_hip_pitch_vel"/>
    <jointvel joint="right_hip_roll_joint" name="right_hip_roll_vel"/>
    <jointvel joint="right_hip_yaw_joint" name="right_hip_yaw_vel"/>
    <jointvel joint="right_knee_joint" name="right_knee_vel"/>
    <jointvel joint="right_ankle_pitch_joint" name="right_ankle_pitch_vel"/>
    <jointvel joint="right_ankle_roll_joint" name="right_ankle_roll_vel"/>
    <jointvel joint="waist_yaw_joint" name="waist_yaw_vel"/>
    <jointvel joint="waist_roll_joint" name="waist_roll_vel"/>
    <jointvel joint="waist_pitch_joint" name="waist_pitch_vel"/>
    <jointvel joint="left_shoulder_pitch_joint" name="left_shoulder_pitch_vel"/>
    <jointvel joint="left_shoulder_roll_joint" name="left_shoulder_roll_vel"/>
    <jointvel joint="left_shoulder_yaw_joint" name="left_shoulder_yaw_vel"/>
    <jointvel joint="left_elbow_joint" name="left_elbow_vel"/>
    <jointvel joint="left_wrist_roll_joint" name="left_wrist_roll_vel"/>
    <jointvel joint="left_wrist_pitch_joint" name="left_wrist_pitch_vel"/>
    <jointvel joint="left_wrist_yaw_joint" name="left_wrist_yaw_vel"/>
    <jointvel joint="right_shoulder_pitch_joint" name="right_shoulder_pitch_vel"/>
    <jointvel joint="right_shoulder_roll_joint" name="right_shoulder_roll_vel"/>
    <jointvel joint="right_shoulder_yaw_joint" name="right_shoulder_yaw_vel"/>
    <jointvel joint="right_elbow_joint" name="right_elbow_vel"/>
    <jointvel joint="right_wrist_roll_joint" name="right_wrist_roll_vel"/>
    <jointvel joint="right_wrist_pitch_joint" name="right_wrist_pitch_vel"/>
    <jointvel joint="right_wrist_yaw_joint" name="right_wrist_yaw_vel"/>
    <jointactuatorfrc joint="left_hip_pitch_joint" name="left_hip_pitch_torque"/>
    <jointactuatorfrc joint="left_hip_roll_joint" name="left_hip_roll_torque"/>
    <jointactuatorfrc joint="left_hip_yaw_joint" name="left_hip_yaw_torque"/>
    <jointactuatorfrc joint="left_knee_joint" name="left_knee_torque"/>
    <jointactuatorfrc joint="left_ankle_pitch_joint" name="left_ankle_pitch_torque"/>
    <jointactuatorfrc joint="left_ankle_roll_joint" name="left_ankle_roll_torque"/>
    <jointactuatorfrc joint="right_hip_pitch_joint" name="right_hip_pitch_torque"/>
    <jointactuatorfrc joint="right_hip_roll_joint" name="right_hip_roll_torque"/>
    <jointactuatorfrc joint="right_hip_yaw_joint" name="right_hip_yaw_torque"/>
    <jointactuatorfrc joint="right_knee_joint" name="right_knee_torque"/>
    <jointactuatorfrc joint="right_ankle_pitch_joint" name="right_ankle_pitch_torque"/>
    <jointactuatorfrc joint="right_ankle_roll_joint" name="right_ankle_roll_torque"/>
    <jointactuatorfrc joint="waist_yaw_joint" name="waist_yaw_torque"/>
    <jointactuatorfrc joint="waist_roll_joint" name="waist_roll_torque"/>
    <jointactuatorfrc joint="waist_pitch_joint" name="waist_pitch_torque"/>
    <jointactuatorfrc joint="left_shoulder_pitch_joint" name="left_shoulder_pitch_torque"/>
    <jointactuatorfrc joint="left_shoulder_roll_joint" name="left_shoulder_roll_torque"/>
    <jointactuatorfrc joint="left_shoulder_yaw_joint" name="left_shoulder_yaw_torque"/>
    <jointactuatorfrc joint="left_elbow_joint" name="left_elbow_torque"/>
    <jointactuatorfrc joint="left_wrist_roll_joint" name="left_wrist_roll_torque"/>
    <jointactuatorfrc joint="left_wrist_pitch_joint" name="left_wrist_pitch_torque"/>
    <jointactuatorfrc joint="left_wrist_yaw_joint" name="left_wrist_yaw_torque"/>
    <jointactuatorfrc joint="right_shoulder_pitch_joint" name="right_shoulder_pitch_torque"/>
    <jointactuatorfrc joint="right_shoulder_roll_joint" name="right_shoulder_roll_torque"/>
    <jointactuatorfrc joint="right_shoulder_yaw_joint" name="right_shoulder_yaw_torque"/>
    <jointactuatorfrc joint="right_elbow_joint" name="right_elbow_torque"/>
    <jointactuatorfrc joint="right_wrist_roll_joint" name="right_wrist_roll_torque"/>
    <jointactuatorfrc joint="right_wrist_pitch_joint" name="right_wrist_pitch_torque"/>
    <jointactuatorfrc joint="right_wrist_yaw_joint" name="right_wrist_yaw_torque"/>
    <framequat objtype="site" objname="imu" name="imu_quat"/>
    <gyro site="imu" name="imu_gyro"/>
    <accelerometer site="imu" name="imu_acc"/>
    <framepos objtype="site" objname="imu" name="frame_pos"/>
    <framelinvel objtype="site" objname="imu" name="frame_vel"/>
    <framequat objtype="site" objname="secondary_imu" name="secondary_imu_quat"/>
    <gyro site="secondary_imu" name="secondary_imu_gyro" cutoff="34.9" noise="0.0005"/>
    <accelerometer site="secondary_imu" name="secondary_imu_acc" cutoff="157" noise="0.01"/>
  </sensor>
</mujoco>
